<?xml version="1.0" encoding="utf-8"?>
<!-- This URDF was automatically created by SolidWorks to URDF Exporter! Originally created by Stephen Brawner (brawner@gmail.com) 
     Commit Version:   Build Version: 1.6.9305.33219
     For more information, please see http://wiki.ros.org/sw_urdf_exporter -->
<robot
  name="screw_26mmhinge_module_cover_0deg">
  <link
    name="base_link">
    <inertial>
      <origin
        xyz="-0.000397243037985137 -0.000299123988951571 0.0268900174967925"
        rpy="0 0 0" />
      <mass
        value="0.0392907478850212" />
      <inertia
        ixx="6.49315163386437E-06"
        ixy="-1.58700153015025E-07"
        ixz="1.07943557378575E-07"
        iyy="7.59585884582494E-06"
        iyz="-1.02493309535865E-09"
        izz="5.32693747823652E-06" />
    </inertial>
    <visual>
      <origin
        xyz="0 0 0"
        rpy="-1.5707963267949 -1.23259516440783E-32 -1.5707963267949" />
      <geometry>
        <mesh
          filename="package://screw_26mmhinge_module_cover_0deg/meshes/base_link.3dxml" />
      </geometry>
      <material
        name="">
        <color
          rgba="0.752941176470588 0.752941176470588 0.752941176470588 1" />
      </material>
    </visual>
    <collision>
      <origin
        xyz="0 0 0"
        rpy="-1.5707963267949 -1.23259516440783E-32 -1.5707963267949" />
      <geometry>
        <mesh
          filename="package://screw_26mmhinge_module_cover_0deg/meshes/base_link.3dxml" />
      </geometry>
    </collision>
  </link>
  <link
    name="link1">
    <inertial>
      <origin
        xyz="0.00050176181802974 0.000131881332311372 0.0261566388593281"
        rpy="0 0 0" />
      <mass
        value="0.015679495466009" />
      <inertia
        ixx="2.36251577154097E-06"
        ixy="-2.28902268828607E-09"
        ixz="1.04881203366641E-08"
        iyy="2.26742863290264E-06"
        iyz="5.68818291644029E-09"
        izz="3.78920030884968E-06" />
    </inertial>
    <visual>
      <origin
        xyz="-4.78706382828717E-18 -2.27356509549241E-13 -0.04"
        rpy="-1.5707963267949 -5.6843768294084E-12 -1.5707963267949" />
      <geometry>
        <mesh
          filename="package://screw_26mmhinge_module_cover_0deg/meshes/link1.3dxml" />
      </geometry>
      <material
        name="">
        <color
          rgba="0.298039215686275 0.298039215686275 0.298039215686275 1" />
      </material>
    </visual>
    <collision>
      <origin
        xyz="-4.78706382828717E-18 -2.27356509549241E-13 -0.04"
        rpy="-1.5707963267949 -5.6843768294084E-12 -1.5707963267949" />
      <geometry>
        <mesh
          filename="package://screw_26mmhinge_module_cover_0deg/meshes/link1.3dxml" />
      </geometry>
    </collision>
  </link>
  <joint
    name="joint1"
    type="revolute">
    <origin
      xyz="0 0 0.04"
      rpy="0 0 0" />
    <parent
      link="base_link" />
    <child
      link="link1" />
    <axis
      xyz="-1 0 0" />
    <limit
      lower="0"
      upper="1.78"
      effort="0"
      velocity="0" />
  </joint>
  <link
    name="dummy_link">
    <inertial>
      <origin
        xyz="-0.0014613136949066 0.000201870283592702 -0.00283550060370832"
        rpy="0 0 0" />
      <mass
        value="0.00131295075943631" />
      <inertia
        ixx="5.41755504446753E-08"
        ixy="1.27650591704971E-09"
        ixz="-4.82976525914748E-09"
        iyy="5.88144881419792E-08"
        iyz="3.56234285325651E-10"
        izz="1.05520720481453E-07" />
    </inertial>
    <visual>
      <origin
        xyz="-5.70310545120184E-14 1.16021683487197E-16 -0.073"
        rpy="-1.57079632679489 -5.5511151231276E-17 2.09425057814711E-14" />
      <geometry>
        <mesh
          filename="package://screw_26mmhinge_module_cover_0deg/meshes/dummy_link.3dxml" />
      </geometry>
      <material
        name="">
        <color
          rgba="0.792156862745098 0.819607843137255 0.933333333333333 1" />
      </material>
    </visual>
    <collision>
      <origin
        xyz="-5.70310545120184E-14 1.16021683487197E-16 -0.073"
        rpy="-1.57079632679489 -5.5511151231276E-17 2.09425057814711E-14" />
      <geometry>
        <mesh
          filename="package://screw_26mmhinge_module_cover_0deg/meshes/dummy_link.3dxml" />
      </geometry>
    </collision>
  </link>
  <joint
    name="dummy_joint"
    type="fixed">
    <origin
      xyz="0 0 0.033"
      rpy="0 0 -1.57079632679492" />
    <parent
      link="link1" />
    <child
      link="dummy_link" />
    <axis
      xyz="0 0 0" />
  </joint>
</robot>